<?xml version="1.0" ?>
<robot name="(Nicht" xmlns:xacro="http://www.ros.org/wiki/xacro">

<xacro:include filename="$(find (Nicht_description)/urdf/materials.xacro" />
<xacro:include filename="$(find (Nicht_description)/urdf/(Nicht.trans" />
<xacro:include filename="$(find (Nicht_description)/urdf/(Nicht.gazebo" />
<link name="base_link">
  <inertial>
    <origin xyz="-0.001790888956705833 5.198855970783829e-16 0.005081280353570841" rpy="0 0 0"/>
    <mass value="0.06973734855496082"/>
    <inertia ixx="2.9e-05" iyy="3e-05" izz="5.3e-05" ixy="-0.0" iyz="0.0" ixz="1e-06"/>
  </inertial>
  <visual>
    <origin xyz="0 0 0" rpy="0 0 0"/>
    <geometry>
      <mesh filename="file://$(find (Nicht_description)/meshes/base_link.stl" scale="0.001 0.001 0.001"/>
    </geometry>
    <material name="silver"/>
  </visual>
  <collision>
    <origin xyz="0 0 0" rpy="0 0 0"/>
    <geometry>
      <mesh filename="file://$(find (Nicht_description)/meshes/base_link.stl" scale="0.001 0.001 0.001"/>
    </geometry>
  </collision>
</link>

<link name="MGArmSprint_v1_1">
  <inertial>
    <origin xyz="-0.022653401703002903 -0.018821031057272345 -0.00048217386530529163" rpy="0 0 0"/>
    <mass value="0.08330869614867872"/>
    <inertia ixx="1.7e-05" iyy="3e-05" izz="4.1e-05" ixy="-9e-06" iyz="-2e-06" ixz="-3e-06"/>
  </inertial>
  <visual>
    <origin xyz="0.0055 0.008 -0.0222" rpy="0 0 0"/>
    <geometry>
      <mesh filename="file://$(find (Nicht_description)/meshes/MGArmSprint_v1_1.stl" scale="0.001 0.001 0.001"/>
    </geometry>
    <material name="silver"/>
  </visual>
  <collision>
    <origin xyz="0.0055 0.008 -0.0222" rpy="0 0 0"/>
    <geometry>
      <mesh filename="file://$(find (Nicht_description)/meshes/MGArmSprint_v1_1.stl" scale="0.001 0.001 0.001"/>
    </geometry>
  </collision>
</link>

<link name="MGArmFront_v1_1">
  <inertial>
    <origin xyz="-0.018054824326861757 -0.018647230418994104 0.0009453273792752494" rpy="0 0 0"/>
    <mass value="0.05087504179859737"/>
    <inertia ixx="1e-05" iyy="1.1e-05" izz="1.9e-05" ixy="-2e-06" iyz="-0.0" ixz="-1e-06"/>
  </inertial>
  <visual>
    <origin xyz="0.059 0.0445 -0.02243" rpy="0 0 0"/>
    <geometry>
      <mesh filename="file://$(find (Nicht_description)/meshes/MGArmFront_v1_1.stl" scale="0.001 0.001 0.001"/>
    </geometry>
    <material name="silver"/>
  </visual>
  <collision>
    <origin xyz="0.059 0.0445 -0.02243" rpy="0 0 0"/>
    <geometry>
      <mesh filename="file://$(find (Nicht_description)/meshes/MGArmFront_v1_1.stl" scale="0.001 0.001 0.001"/>
    </geometry>
  </collision>
</link>

<joint name="Umdrehung 5" type="continuous">
  <origin xyz="-0.0055 -0.008 0.0222" rpy="0 0 0"/>
  <parent link="base_link"/>
  <child link="MGArmSprint_v1_1"/>
  <axis xyz="0.0 -1.0 0.0"/>
</joint>

<joint name="Umdrehung 6" type="continuous">
  <origin xyz="-0.0535 -0.0365 0.00023" rpy="0 0 0"/>
  <parent link="MGArmSprint_v1_1"/>
  <child link="MGArmFront_v1_1"/>
  <axis xyz="0.0 -1.0 0.0"/>
</joint>

</robot>
